2024-07-29 09:04:35,751 ERROR не найден пользователь в БД или конфигурации VPN: A request to the Telegram API was unsuccessful. Error code: 400. Description: Bad Request: chat not found
2024-07-29 09:04:36,038 ERROR не найден пользователь в БД или конфигурации VPN: A request to the Telegram API was unsuccessful. Error code: 400. Description: Bad Request: chat not found
2024-07-29 09:04:36,517 ERROR не найден пользователь в БД или конфигурации VPN: A request to the Telegram API was unsuccessful. Error code: 400. Description: Bad Request: chat not found
2024-07-29 09:04:36,982 ERROR не найден пользователь в БД или конфигурации VPN: A request to the Telegram API was unsuccessful. Error code: 400. Description: Bad Request: chat not found
2024-07-29 09:04:37,480 ERROR не найден пользователь в БД или конфигурации VPN: A request to the Telegram API was unsuccessful. Error code: 400. Description: Bad Request: chat not found
2024-07-29 09:04:37,942 ERROR не найден пользователь в БД или конфигурации VPN: A request to the Telegram API was unsuccessful. Error code: 400. Description: Bad Request: chat not found
2024-07-29 09:04:38,457 ERROR не найден пользователь в БД или конфигурации VPN: A request to the Telegram API was unsuccessful. Error code: 400. Description: Bad Request: chat not found
2024-07-29 09:04:39,008 ERROR не найден пользователь в БД или конфигурации VPN: A request to the Telegram API was unsuccessful. Error code: 400. Description: Bad Request: chat not found
2024-07-29 09:04:39,752 ERROR не найден пользователь в БД или конфигурации VPN: A request to the Telegram API was unsuccessful. Error code: 400. Description: Bad Request: chat not found
2024-07-29 09:04:40,556 ERROR не найден пользователь в БД или конфигурации VPN: A request to the Telegram API was unsuccessful. Error code: 400. Description: Bad Request: chat not found
2024-07-29 09:04:41,184 ERROR не найден пользователь в БД или конфигурации VPN: A request to the Telegram API was unsuccessful. Error code: 400. Description: Bad Request: chat not found
2024-07-29 09:04:41,677 ERROR не найден пользователь в БД или конфигурации VPN: A request to the Telegram API was unsuccessful. Error code: 400. Description: Bad Request: chat not found
2024-07-29 09:05:31,370 INFO chat: None, user:Максим Кузнецов нажата кнопка с ключем page_client_next
2024-07-31 09:39:01,184 ERROR Не удалось подключиться к БД
2024-07-31 09:39:27,488 ERROR Не удалось подключиться к БД
2024-07-31 09:39:47,405 ERROR Не удалось подключиться к БД
2024-07-31 09:40:57,848 ERROR Не удалось подключиться к БД
2024-07-31 09:41:45,384 ERROR Не удалось подключиться к БД
2024-07-31 09:42:23,660 ERROR Не удалось подключиться к БД
2024-07-31 09:42:56,983 ERROR Threaded polling exception: A request to the Telegram API was unsuccessful. Error code: 409. Description: Conflict: terminated by other getUpdates request; make sure that only one bot instance is running
2024-07-31 09:42:56,983 ERROR Exception traceback:
Traceback (most recent call last):
  File "/Library/Frameworks/Python.framework/Versions/3.10/lib/python3.10/site-packages/telebot/__init__.py", line 1073, in __threaded_polling
    polling_thread.raise_exceptions()
  File "/Library/Frameworks/Python.framework/Versions/3.10/lib/python3.10/site-packages/telebot/util.py", line 108, in raise_exceptions
    raise self.exception_info
  File "/Library/Frameworks/Python.framework/Versions/3.10/lib/python3.10/site-packages/telebot/util.py", line 90, in run
    task(*args, **kwargs)
  File "/Library/Frameworks/Python.framework/Versions/3.10/lib/python3.10/site-packages/telebot/__init__.py", line 649, in __retrieve_updates
    updates = self.get_updates(offset=(self.last_update_id + 1),
  File "/Library/Frameworks/Python.framework/Versions/3.10/lib/python3.10/site-packages/telebot/__init__.py", line 623, in get_updates
    json_updates = apihelper.get_updates(self.token, offset, limit, timeout, allowed_updates, long_polling_timeout)
  File "/Library/Frameworks/Python.framework/Versions/3.10/lib/python3.10/site-packages/telebot/apihelper.py", line 321, in get_updates
    return _make_request(token, method_url, params=payload)
  File "/Library/Frameworks/Python.framework/Versions/3.10/lib/python3.10/site-packages/telebot/apihelper.py", line 162, in _make_request
    json_result = _check_result(method_name, result)
  File "/Library/Frameworks/Python.framework/Versions/3.10/lib/python3.10/site-packages/telebot/apihelper.py", line 189, in _check_result
    raise ApiTelegramException(method_name, result, result_json)
telebot.apihelper.ApiTelegramException: A request to the Telegram API was unsuccessful. Error code: 409. Description: Conflict: terminated by other getUpdates request; make sure that only one bot instance is running

2024-07-31 09:44:51,892 ERROR Threaded polling exception: A request to the Telegram API was unsuccessful. Error code: 409. Description: Conflict: terminated by other getUpdates request; make sure that only one bot instance is running
2024-07-31 09:44:51,893 ERROR Exception traceback:
Traceback (most recent call last):
  File "/Library/Frameworks/Python.framework/Versions/3.10/lib/python3.10/site-packages/telebot/__init__.py", line 1073, in __threaded_polling
    polling_thread.raise_exceptions()
  File "/Library/Frameworks/Python.framework/Versions/3.10/lib/python3.10/site-packages/telebot/util.py", line 108, in raise_exceptions
    raise self.exception_info
  File "/Library/Frameworks/Python.framework/Versions/3.10/lib/python3.10/site-packages/telebot/util.py", line 90, in run
    task(*args, **kwargs)
  File "/Library/Frameworks/Python.framework/Versions/3.10/lib/python3.10/site-packages/telebot/__init__.py", line 649, in __retrieve_updates
    updates = self.get_updates(offset=(self.last_update_id + 1),
  File "/Library/Frameworks/Python.framework/Versions/3.10/lib/python3.10/site-packages/telebot/__init__.py", line 623, in get_updates
    json_updates = apihelper.get_updates(self.token, offset, limit, timeout, allowed_updates, long_polling_timeout)
  File "/Library/Frameworks/Python.framework/Versions/3.10/lib/python3.10/site-packages/telebot/apihelper.py", line 321, in get_updates
    return _make_request(token, method_url, params=payload)
  File "/Library/Frameworks/Python.framework/Versions/3.10/lib/python3.10/site-packages/telebot/apihelper.py", line 162, in _make_request
    json_result = _check_result(method_name, result)
  File "/Library/Frameworks/Python.framework/Versions/3.10/lib/python3.10/site-packages/telebot/apihelper.py", line 189, in _check_result
    raise ApiTelegramException(method_name, result, result_json)
telebot.apihelper.ApiTelegramException: A request to the Telegram API was unsuccessful. Error code: 409. Description: Conflict: terminated by other getUpdates request; make sure that only one bot instance is running

2024-07-31 11:07:34,438 ERROR Threaded polling exception: A request to the Telegram API was unsuccessful. Error code: 409. Description: Conflict: terminated by other getUpdates request; make sure that only one bot instance is running
2024-07-31 11:07:34,439 ERROR Exception traceback:
Traceback (most recent call last):
  File "/Library/Frameworks/Python.framework/Versions/3.10/lib/python3.10/site-packages/telebot/__init__.py", line 1073, in __threaded_polling
    polling_thread.raise_exceptions()
  File "/Library/Frameworks/Python.framework/Versions/3.10/lib/python3.10/site-packages/telebot/util.py", line 108, in raise_exceptions
    raise self.exception_info
  File "/Library/Frameworks/Python.framework/Versions/3.10/lib/python3.10/site-packages/telebot/util.py", line 90, in run
    task(*args, **kwargs)
  File "/Library/Frameworks/Python.framework/Versions/3.10/lib/python3.10/site-packages/telebot/__init__.py", line 649, in __retrieve_updates
    updates = self.get_updates(offset=(self.last_update_id + 1),
  File "/Library/Frameworks/Python.framework/Versions/3.10/lib/python3.10/site-packages/telebot/__init__.py", line 623, in get_updates
    json_updates = apihelper.get_updates(self.token, offset, limit, timeout, allowed_updates, long_polling_timeout)
  File "/Library/Frameworks/Python.framework/Versions/3.10/lib/python3.10/site-packages/telebot/apihelper.py", line 321, in get_updates
    return _make_request(token, method_url, params=payload)
  File "/Library/Frameworks/Python.framework/Versions/3.10/lib/python3.10/site-packages/telebot/apihelper.py", line 162, in _make_request
    json_result = _check_result(method_name, result)
  File "/Library/Frameworks/Python.framework/Versions/3.10/lib/python3.10/site-packages/telebot/apihelper.py", line 189, in _check_result
    raise ApiTelegramException(method_name, result, result_json)
telebot.apihelper.ApiTelegramException: A request to the Telegram API was unsuccessful. Error code: 409. Description: Conflict: terminated by other getUpdates request; make sure that only one bot instance is running

2024-07-31 12:27:24,005 ERROR Infinity polling exception: LIMIT #,# syntax is not supported
LINE 1: ..., paid FROM users_subscription  ORDER BY id DESC  LIMIT 0, 6
                                                             ^
HINT:  Use separate LIMIT and OFFSET clauses.

2024-07-31 12:27:24,006 ERROR Exception traceback:
Traceback (most recent call last):
  File "/Library/Frameworks/Python.framework/Versions/3.10/lib/python3.10/site-packages/telebot/__init__.py", line 955, in infinity_polling
    self.polling(non_stop=True, timeout=timeout, long_polling_timeout=long_polling_timeout,
  File "/Library/Frameworks/Python.framework/Versions/3.10/lib/python3.10/site-packages/telebot/__init__.py", line 1043, in polling
    self.__threaded_polling(non_stop=non_stop, interval=interval, timeout=timeout, long_polling_timeout=long_polling_timeout,
  File "/Library/Frameworks/Python.framework/Versions/3.10/lib/python3.10/site-packages/telebot/__init__.py", line 1118, in __threaded_polling
    raise e
  File "/Library/Frameworks/Python.framework/Versions/3.10/lib/python3.10/site-packages/telebot/__init__.py", line 1074, in __threaded_polling
    self.worker_pool.raise_exceptions()
  File "/Library/Frameworks/Python.framework/Versions/3.10/lib/python3.10/site-packages/telebot/util.py", line 147, in raise_exceptions
    raise self.exception_info
  File "/Library/Frameworks/Python.framework/Versions/3.10/lib/python3.10/site-packages/telebot/util.py", line 90, in run
    task(*args, **kwargs)
  File "/Library/Frameworks/Python.framework/Versions/3.10/lib/python3.10/site-packages/telebot/__init__.py", line 6788, in _run_middlewares_and_handler
    result = handler['function'](message)
  File "/Users/mkuznecov/my_projects/bot_vpn/bot_vpn.py", line 60, in d
    manager_users_list.search_all_user(message)
  File "/Users/mkuznecov/my_projects/bot_vpn/managment_user.py", line 33, in search_all_user
    cursor.execute("SELECT name, telegram_id, action, exit_date, server_id, paid FROM users_subscription " +
psycopg2.errors.SyntaxError: LIMIT #,# syntax is not supported
LINE 1: ..., paid FROM users_subscription  ORDER BY id DESC  LIMIT 0, 6
                                                             ^
HINT:  Use separate LIMIT and OFFSET clauses.


2024-07-31 12:28:37,938 ERROR Infinity polling exception: LIMIT #,# syntax is not supported
LINE 1: ...it_date, server_id, paid FROM users_subscription  LIMIT 0, 6
                                                             ^
HINT:  Use separate LIMIT and OFFSET clauses.

2024-07-31 12:28:37,938 ERROR Exception traceback:
Traceback (most recent call last):
  File "/Library/Frameworks/Python.framework/Versions/3.10/lib/python3.10/site-packages/telebot/__init__.py", line 955, in infinity_polling
    self.polling(non_stop=True, timeout=timeout, long_polling_timeout=long_polling_timeout,
  File "/Library/Frameworks/Python.framework/Versions/3.10/lib/python3.10/site-packages/telebot/__init__.py", line 1043, in polling
    self.__threaded_polling(non_stop=non_stop, interval=interval, timeout=timeout, long_polling_timeout=long_polling_timeout,
  File "/Library/Frameworks/Python.framework/Versions/3.10/lib/python3.10/site-packages/telebot/__init__.py", line 1118, in __threaded_polling
    raise e
  File "/Library/Frameworks/Python.framework/Versions/3.10/lib/python3.10/site-packages/telebot/__init__.py", line 1074, in __threaded_polling
    self.worker_pool.raise_exceptions()
  File "/Library/Frameworks/Python.framework/Versions/3.10/lib/python3.10/site-packages/telebot/util.py", line 147, in raise_exceptions
    raise self.exception_info
  File "/Library/Frameworks/Python.framework/Versions/3.10/lib/python3.10/site-packages/telebot/util.py", line 90, in run
    task(*args, **kwargs)
  File "/Library/Frameworks/Python.framework/Versions/3.10/lib/python3.10/site-packages/telebot/__init__.py", line 6788, in _run_middlewares_and_handler
    result = handler['function'](message)
  File "/Users/mkuznecov/my_projects/bot_vpn/bot_vpn.py", line 60, in d
    manager_users_list.search_all_user(message)
  File "/Users/mkuznecov/my_projects/bot_vpn/managment_user.py", line 33, in search_all_user
    cursor.execute("SELECT name, telegram_id, action, exit_date, server_id, paid FROM users_subscription " +
psycopg2.errors.SyntaxError: LIMIT #,# syntax is not supported
LINE 1: ...it_date, server_id, paid FROM users_subscription  LIMIT 0, 6
                                                             ^
HINT:  Use separate LIMIT and OFFSET clauses.


2024-07-31 12:29:36,262 ERROR Infinity polling exception: 'UserList' object has no attribute 'data_cur'
2024-07-31 12:29:36,262 ERROR Exception traceback:
Traceback (most recent call last):
  File "/Library/Frameworks/Python.framework/Versions/3.10/lib/python3.10/site-packages/telebot/__init__.py", line 955, in infinity_polling
    self.polling(non_stop=True, timeout=timeout, long_polling_timeout=long_polling_timeout,
  File "/Library/Frameworks/Python.framework/Versions/3.10/lib/python3.10/site-packages/telebot/__init__.py", line 1043, in polling
    self.__threaded_polling(non_stop=non_stop, interval=interval, timeout=timeout, long_polling_timeout=long_polling_timeout,
  File "/Library/Frameworks/Python.framework/Versions/3.10/lib/python3.10/site-packages/telebot/__init__.py", line 1118, in __threaded_polling
    raise e
  File "/Library/Frameworks/Python.framework/Versions/3.10/lib/python3.10/site-packages/telebot/__init__.py", line 1074, in __threaded_polling
    self.worker_pool.raise_exceptions()
  File "/Library/Frameworks/Python.framework/Versions/3.10/lib/python3.10/site-packages/telebot/util.py", line 147, in raise_exceptions
    raise self.exception_info
  File "/Library/Frameworks/Python.framework/Versions/3.10/lib/python3.10/site-packages/telebot/util.py", line 90, in run
    task(*args, **kwargs)
  File "/Library/Frameworks/Python.framework/Versions/3.10/lib/python3.10/site-packages/telebot/__init__.py", line 6788, in _run_middlewares_and_handler
    result = handler['function'](message)
  File "/Users/mkuznecov/my_projects/bot_vpn/bot_vpn.py", line 60, in d
    manager_users_list.search_all_user(message)
  File "/Users/mkuznecov/my_projects/bot_vpn/managment_user.py", line 38, in search_all_user
    self.manager_users_list(message, cursor.fetchall())
  File "/Users/mkuznecov/my_projects/bot_vpn/managment_user.py", line 60, in manager_users_list
    if len(self.data_cur) == 0:
AttributeError: 'UserList' object has no attribute 'data_cur'

2024-07-31 12:31:33,160 ERROR Infinity polling exception: 'UserList' object has no attribute 'data_cur'
2024-07-31 12:31:33,160 ERROR Exception traceback:
Traceback (most recent call last):
  File "/Library/Frameworks/Python.framework/Versions/3.10/lib/python3.10/site-packages/telebot/__init__.py", line 955, in infinity_polling
    self.polling(non_stop=True, timeout=timeout, long_polling_timeout=long_polling_timeout,
  File "/Library/Frameworks/Python.framework/Versions/3.10/lib/python3.10/site-packages/telebot/__init__.py", line 1043, in polling
    self.__threaded_polling(non_stop=non_stop, interval=interval, timeout=timeout, long_polling_timeout=long_polling_timeout,
  File "/Library/Frameworks/Python.framework/Versions/3.10/lib/python3.10/site-packages/telebot/__init__.py", line 1118, in __threaded_polling
    raise e
  File "/Library/Frameworks/Python.framework/Versions/3.10/lib/python3.10/site-packages/telebot/__init__.py", line 1074, in __threaded_polling
    self.worker_pool.raise_exceptions()
  File "/Library/Frameworks/Python.framework/Versions/3.10/lib/python3.10/site-packages/telebot/util.py", line 147, in raise_exceptions
    raise self.exception_info
  File "/Library/Frameworks/Python.framework/Versions/3.10/lib/python3.10/site-packages/telebot/util.py", line 90, in run
    task(*args, **kwargs)
  File "/Library/Frameworks/Python.framework/Versions/3.10/lib/python3.10/site-packages/telebot/__init__.py", line 6788, in _run_middlewares_and_handler
    result = handler['function'](message)
  File "/Users/mkuznecov/my_projects/bot_vpn/bot_vpn.py", line 60, in d
    manager_users_list.search_all_user(message)
  File "/Users/mkuznecov/my_projects/bot_vpn/managment_user.py", line 38, in search_all_user
    self.manager_users_list(message, cursor.fetchall())
  File "/Users/mkuznecov/my_projects/bot_vpn/managment_user.py", line 61, in manager_users_list
    if len(self.data_cur) == 0:
AttributeError: 'UserList' object has no attribute 'data_cur'

2024-07-31 12:33:44,077 ERROR Infinity polling exception: can only concatenate str (not "datetime.datetime") to str
2024-07-31 12:33:44,078 ERROR Exception traceback:
Traceback (most recent call last):
  File "/Library/Frameworks/Python.framework/Versions/3.10/lib/python3.10/site-packages/telebot/__init__.py", line 955, in infinity_polling
    self.polling(non_stop=True, timeout=timeout, long_polling_timeout=long_polling_timeout,
  File "/Library/Frameworks/Python.framework/Versions/3.10/lib/python3.10/site-packages/telebot/__init__.py", line 1043, in polling
    self.__threaded_polling(non_stop=non_stop, interval=interval, timeout=timeout, long_polling_timeout=long_polling_timeout,
  File "/Library/Frameworks/Python.framework/Versions/3.10/lib/python3.10/site-packages/telebot/__init__.py", line 1118, in __threaded_polling
    raise e
  File "/Library/Frameworks/Python.framework/Versions/3.10/lib/python3.10/site-packages/telebot/__init__.py", line 1074, in __threaded_polling
    self.worker_pool.raise_exceptions()
  File "/Library/Frameworks/Python.framework/Versions/3.10/lib/python3.10/site-packages/telebot/util.py", line 147, in raise_exceptions
    raise self.exception_info
  File "/Library/Frameworks/Python.framework/Versions/3.10/lib/python3.10/site-packages/telebot/util.py", line 90, in run
    task(*args, **kwargs)
  File "/Library/Frameworks/Python.framework/Versions/3.10/lib/python3.10/site-packages/telebot/__init__.py", line 6788, in _run_middlewares_and_handler
    result = handler['function'](message)
  File "/Users/mkuznecov/my_projects/bot_vpn/bot_vpn.py", line 60, in d
    manager_users_list.search_all_user(message)
  File "/Users/mkuznecov/my_projects/bot_vpn/managment_user.py", line 38, in search_all_user
    self.manager_users_list(message, cursor.fetchall())
  File "/Users/mkuznecov/my_projects/bot_vpn/managment_user.py", line 93, in manager_users_list
    paid + status + "[" + utils.form_text_markdownv2(i[0]) +
TypeError: can only concatenate str (not "datetime.datetime") to str

2024-07-31 12:34:58,009 ERROR Infinity polling exception: can only concatenate str (not "datetime.datetime") to str
2024-07-31 12:34:58,009 ERROR Exception traceback:
Traceback (most recent call last):
  File "/Library/Frameworks/Python.framework/Versions/3.10/lib/python3.10/site-packages/telebot/__init__.py", line 955, in infinity_polling
    self.polling(non_stop=True, timeout=timeout, long_polling_timeout=long_polling_timeout,
  File "/Library/Frameworks/Python.framework/Versions/3.10/lib/python3.10/site-packages/telebot/__init__.py", line 1043, in polling
    self.__threaded_polling(non_stop=non_stop, interval=interval, timeout=timeout, long_polling_timeout=long_polling_timeout,
  File "/Library/Frameworks/Python.framework/Versions/3.10/lib/python3.10/site-packages/telebot/__init__.py", line 1118, in __threaded_polling
    raise e
  File "/Library/Frameworks/Python.framework/Versions/3.10/lib/python3.10/site-packages/telebot/__init__.py", line 1074, in __threaded_polling
    self.worker_pool.raise_exceptions()
  File "/Library/Frameworks/Python.framework/Versions/3.10/lib/python3.10/site-packages/telebot/util.py", line 147, in raise_exceptions
    raise self.exception_info
  File "/Library/Frameworks/Python.framework/Versions/3.10/lib/python3.10/site-packages/telebot/util.py", line 90, in run
    task(*args, **kwargs)
  File "/Library/Frameworks/Python.framework/Versions/3.10/lib/python3.10/site-packages/telebot/__init__.py", line 6788, in _run_middlewares_and_handler
    result = handler['function'](message)
  File "/Users/mkuznecov/my_projects/bot_vpn/bot_vpn.py", line 60, in d
    manager_users_list.search_all_user(message)
  File "/Users/mkuznecov/my_projects/bot_vpn/managment_user.py", line 38, in search_all_user
    self.manager_users_list(message, cursor.fetchall())
  File "/Users/mkuznecov/my_projects/bot_vpn/managment_user.py", line 93, in manager_users_list
    paid + status + "[" + str(utils.form_text_markdownv2(i[0])) +
TypeError: can only concatenate str (not "datetime.datetime") to str

2024-07-31 12:42:56,485 INFO Бот запущен пользователем со статусом True
2024-07-31 12:42:56,782 ERROR Infinity polling exception: [Errno 2] No such file or directory: '/root/bot_vpn/vpn_on.jpg'
2024-07-31 12:42:56,783 ERROR Exception traceback:
Traceback (most recent call last):
  File "/Library/Frameworks/Python.framework/Versions/3.10/lib/python3.10/site-packages/telebot/__init__.py", line 955, in infinity_polling
    self.polling(non_stop=True, timeout=timeout, long_polling_timeout=long_polling_timeout,
  File "/Library/Frameworks/Python.framework/Versions/3.10/lib/python3.10/site-packages/telebot/__init__.py", line 1043, in polling
    self.__threaded_polling(non_stop=non_stop, interval=interval, timeout=timeout, long_polling_timeout=long_polling_timeout,
  File "/Library/Frameworks/Python.framework/Versions/3.10/lib/python3.10/site-packages/telebot/__init__.py", line 1118, in __threaded_polling
    raise e
  File "/Library/Frameworks/Python.framework/Versions/3.10/lib/python3.10/site-packages/telebot/__init__.py", line 1074, in __threaded_polling
    self.worker_pool.raise_exceptions()
  File "/Library/Frameworks/Python.framework/Versions/3.10/lib/python3.10/site-packages/telebot/util.py", line 147, in raise_exceptions
    raise self.exception_info
  File "/Library/Frameworks/Python.framework/Versions/3.10/lib/python3.10/site-packages/telebot/util.py", line 90, in run
    task(*args, **kwargs)
  File "/Library/Frameworks/Python.framework/Versions/3.10/lib/python3.10/site-packages/telebot/__init__.py", line 6788, in _run_middlewares_and_handler
    result = handler['function'](message)
  File "/Users/mkuznecov/my_projects/bot_vpn/bot_vpn.py", line 160, in start
    successfully_paid(message.from_user.id)
  File "/Users/mkuznecov/my_projects/bot_vpn/bot_vpn.py", line 32, in successfully_paid
    if bot.send_photo(id, open(config.FILE_URL + "vpn_on.jpg", "rb"),"*Спасибо что выбрали наш сервис\.*\n\nVPN готов к работе\. Для доступа необходимо скачать приложение для вашей платформы \(ссылки ниже по сообщению\), вставить в приложение ваш персональную ссылку\-ключ и нажать подключиться\.\n\nСсылка\-ключ: \n`" +
FileNotFoundError: [Errno 2] No such file or directory: '/root/bot_vpn/vpn_on.jpg'

2024-07-31 12:43:12,492 ERROR Infinity polling exception: 'NoneType' object is not subscriptable
2024-07-31 12:43:12,494 ERROR Exception traceback:
Traceback (most recent call last):
  File "/Library/Frameworks/Python.framework/Versions/3.10/lib/python3.10/site-packages/telebot/__init__.py", line 955, in infinity_polling
    self.polling(non_stop=True, timeout=timeout, long_polling_timeout=long_polling_timeout,
  File "/Library/Frameworks/Python.framework/Versions/3.10/lib/python3.10/site-packages/telebot/__init__.py", line 1043, in polling
    self.__threaded_polling(non_stop=non_stop, interval=interval, timeout=timeout, long_polling_timeout=long_polling_timeout,
  File "/Library/Frameworks/Python.framework/Versions/3.10/lib/python3.10/site-packages/telebot/__init__.py", line 1118, in __threaded_polling
    raise e
  File "/Library/Frameworks/Python.framework/Versions/3.10/lib/python3.10/site-packages/telebot/__init__.py", line 1074, in __threaded_polling
    self.worker_pool.raise_exceptions()
  File "/Library/Frameworks/Python.framework/Versions/3.10/lib/python3.10/site-packages/telebot/util.py", line 147, in raise_exceptions
    raise self.exception_info
  File "/Library/Frameworks/Python.framework/Versions/3.10/lib/python3.10/site-packages/telebot/util.py", line 90, in run
    task(*args, **kwargs)
  File "/Library/Frameworks/Python.framework/Versions/3.10/lib/python3.10/site-packages/telebot/__init__.py", line 6788, in _run_middlewares_and_handler
    result = handler['function'](message)
  File "/Users/mkuznecov/my_projects/bot_vpn/bot_vpn.py", line 141, in start
    logging.info("Бот запущен пользователем со статусом " + str(status["action"]))
TypeError: 'NoneType' object is not subscriptable

2024-07-31 12:49:47,511 INFO chat: None, user:Максим Кузнецов нажата кнопка с ключем page_client_next
2024-07-31 12:49:49,000 INFO chat: None, user:Максим Кузнецов нажата кнопка с ключем page_client_next
2024-07-31 12:49:50,240 INFO chat: None, user:Максим Кузнецов нажата кнопка с ключем page_client_next
2024-07-31 12:49:51,884 INFO chat: None, user:Максим Кузнецов нажата кнопка с ключем page_client_next
2024-07-31 12:49:53,400 INFO chat: None, user:Максим Кузнецов нажата кнопка с ключем page_client_next
2024-07-31 12:49:54,830 INFO chat: None, user:Максим Кузнецов нажата кнопка с ключем page_client_next
2024-07-31 12:49:56,301 INFO chat: None, user:Максим Кузнецов нажата кнопка с ключем page_client_back
2024-07-31 12:49:57,660 INFO chat: None, user:Максим Кузнецов нажата кнопка с ключем page_client_next
2024-07-31 12:49:58,855 INFO chat: None, user:Максим Кузнецов нажата кнопка с ключем page_client_back
2024-07-31 12:50:00,018 INFO chat: None, user:Максим Кузнецов нажата кнопка с ключем page_client_back
2024-07-31 12:50:01,137 INFO chat: None, user:Максим Кузнецов нажата кнопка с ключем page_client_back
2024-07-31 12:50:02,532 INFO chat: None, user:Максим Кузнецов нажата кнопка с ключем page_client_back
2024-07-31 12:50:03,866 INFO chat: None, user:Максим Кузнецов нажата кнопка с ключем page_client_back
2024-07-31 12:50:05,178 INFO chat: None, user:Максим Кузнецов нажата кнопка с ключем page_client_back
2024-07-31 12:50:13,388 INFO chat: None, user:Максим Кузнецов нажата кнопка с ключем try
2024-07-31 12:50:13,650 INFO добавляю user: Максим Кузнецов
2024-07-31 12:50:14,132 ERROR Infinity polling exception: column "user_on_server" of relation "users_subscription" does not exist
LINE 1: ...bscription (telegram_id, name, exit_date, action, user_on_se...
                                                             ^

2024-07-31 12:50:14,132 ERROR Exception traceback:
Traceback (most recent call last):
  File "/Library/Frameworks/Python.framework/Versions/3.10/lib/python3.10/site-packages/telebot/__init__.py", line 955, in infinity_polling
    self.polling(non_stop=True, timeout=timeout, long_polling_timeout=long_polling_timeout,
  File "/Library/Frameworks/Python.framework/Versions/3.10/lib/python3.10/site-packages/telebot/__init__.py", line 1043, in polling
    self.__threaded_polling(non_stop=non_stop, interval=interval, timeout=timeout, long_polling_timeout=long_polling_timeout,
  File "/Library/Frameworks/Python.framework/Versions/3.10/lib/python3.10/site-packages/telebot/__init__.py", line 1118, in __threaded_polling
    raise e
  File "/Library/Frameworks/Python.framework/Versions/3.10/lib/python3.10/site-packages/telebot/__init__.py", line 1074, in __threaded_polling
    self.worker_pool.raise_exceptions()
  File "/Library/Frameworks/Python.framework/Versions/3.10/lib/python3.10/site-packages/telebot/util.py", line 147, in raise_exceptions
    raise self.exception_info
  File "/Library/Frameworks/Python.framework/Versions/3.10/lib/python3.10/site-packages/telebot/util.py", line 90, in run
    task(*args, **kwargs)
  File "/Library/Frameworks/Python.framework/Versions/3.10/lib/python3.10/site-packages/telebot/__init__.py", line 6788, in _run_middlewares_and_handler
    result = handler['function'](message)
  File "/Users/mkuznecov/my_projects/bot_vpn/bot_vpn.py", line 248, in callback_woker
    datetime_exit = add_token(call.from_user.id,
  File "/Users/mkuznecov/my_projects/bot_vpn/managment_user.py", line 210, in add_token
    add_user(id_user, date_time_exit, name_user=name_user, niderland=niderland, invitedId=invitedId)
  File "/Users/mkuznecov/my_projects/bot_vpn/managment_user.py", line 229, in add_user
    cursor.execute("INSERT INTO users_subscription (telegram_id, name, exit_date, action, user_on_server, server_link, server_id)" +
psycopg2.errors.UndefinedColumn: column "user_on_server" of relation "users_subscription" does not exist
LINE 1: ...bscription (telegram_id, name, exit_date, action, user_on_se...
                                                             ^


2024-07-31 12:51:30,859 INFO chat: None, user:Максим Кузнецов нажата кнопка с ключем try
2024-07-31 12:51:31,035 INFO добавляю user: Максим Кузнецов
2024-07-31 12:51:31,489 ERROR Infinity polling exception: invalid input syntax for type bigint: "USA"
LINE 2: ...WpBcmRCbnVBWFdzR0dW@80.209.243.179:3333/?outline=1', 'USA');
                                                                ^

2024-07-31 12:51:31,490 ERROR Exception traceback:
Traceback (most recent call last):
  File "/Library/Frameworks/Python.framework/Versions/3.10/lib/python3.10/site-packages/telebot/__init__.py", line 955, in infinity_polling
    self.polling(non_stop=True, timeout=timeout, long_polling_timeout=long_polling_timeout,
  File "/Library/Frameworks/Python.framework/Versions/3.10/lib/python3.10/site-packages/telebot/__init__.py", line 1043, in polling
    self.__threaded_polling(non_stop=non_stop, interval=interval, timeout=timeout, long_polling_timeout=long_polling_timeout,
  File "/Library/Frameworks/Python.framework/Versions/3.10/lib/python3.10/site-packages/telebot/__init__.py", line 1118, in __threaded_polling
    raise e
  File "/Library/Frameworks/Python.framework/Versions/3.10/lib/python3.10/site-packages/telebot/__init__.py", line 1074, in __threaded_polling
    self.worker_pool.raise_exceptions()
  File "/Library/Frameworks/Python.framework/Versions/3.10/lib/python3.10/site-packages/telebot/util.py", line 147, in raise_exceptions
    raise self.exception_info
  File "/Library/Frameworks/Python.framework/Versions/3.10/lib/python3.10/site-packages/telebot/util.py", line 90, in run
    task(*args, **kwargs)
  File "/Library/Frameworks/Python.framework/Versions/3.10/lib/python3.10/site-packages/telebot/__init__.py", line 6788, in _run_middlewares_and_handler
    result = handler['function'](message)
  File "/Users/mkuznecov/my_projects/bot_vpn/bot_vpn.py", line 248, in callback_woker
    datetime_exit = add_token(call.from_user.id,
  File "/Users/mkuznecov/my_projects/bot_vpn/managment_user.py", line 210, in add_token
    add_user(id_user, date_time_exit, name_user=name_user, niderland=niderland, invitedId=invitedId)
  File "/Users/mkuznecov/my_projects/bot_vpn/managment_user.py", line 229, in add_user
    cursor.execute("INSERT INTO users_subscription (telegram_id, name, exit_date, action, user_on_server_id, server_link, server_id)" +
psycopg2.errors.InvalidTextRepresentation: invalid input syntax for type bigint: "USA"
LINE 2: ...WpBcmRCbnVBWFdzR0dW@80.209.243.179:3333/?outline=1', 'USA');
                                                                ^


2024-07-31 12:52:45,709 INFO chat: None, user:Максим Кузнецов нажата кнопка с ключем try
2024-07-31 12:52:45,884 INFO добавляю user: Максим Кузнецов
2024-07-31 12:52:46,277 ERROR Infinity polling exception: can only concatenate str (not "int") to str
2024-07-31 12:52:46,277 ERROR Exception traceback:
Traceback (most recent call last):
  File "/Library/Frameworks/Python.framework/Versions/3.10/lib/python3.10/site-packages/telebot/__init__.py", line 955, in infinity_polling
    self.polling(non_stop=True, timeout=timeout, long_polling_timeout=long_polling_timeout,
  File "/Library/Frameworks/Python.framework/Versions/3.10/lib/python3.10/site-packages/telebot/__init__.py", line 1043, in polling
    self.__threaded_polling(non_stop=non_stop, interval=interval, timeout=timeout, long_polling_timeout=long_polling_timeout,
  File "/Library/Frameworks/Python.framework/Versions/3.10/lib/python3.10/site-packages/telebot/__init__.py", line 1118, in __threaded_polling
    raise e
  File "/Library/Frameworks/Python.framework/Versions/3.10/lib/python3.10/site-packages/telebot/__init__.py", line 1074, in __threaded_polling
    self.worker_pool.raise_exceptions()
  File "/Library/Frameworks/Python.framework/Versions/3.10/lib/python3.10/site-packages/telebot/util.py", line 147, in raise_exceptions
    raise self.exception_info
  File "/Library/Frameworks/Python.framework/Versions/3.10/lib/python3.10/site-packages/telebot/util.py", line 90, in run
    task(*args, **kwargs)
  File "/Library/Frameworks/Python.framework/Versions/3.10/lib/python3.10/site-packages/telebot/__init__.py", line 6788, in _run_middlewares_and_handler
    result = handler['function'](message)
  File "/Users/mkuznecov/my_projects/bot_vpn/bot_vpn.py", line 248, in callback_woker
    datetime_exit = add_token(call.from_user.id,
  File "/Users/mkuznecov/my_projects/bot_vpn/managment_user.py", line 210, in add_token
    add_user(id_user, date_time_exit, name_user=name_user, niderland=niderland, invitedId=invitedId)
  File "/Users/mkuznecov/my_projects/bot_vpn/managment_user.py", line 229, in add_user
    cursor.execute("INSERT INTO users_subscription (telegram_id, name, exit_date, action, user_on_server_id, server_link, server_id)" +
TypeError: can only concatenate str (not "int") to str

2024-07-31 12:53:39,677 INFO chat: None, user:Максим Кузнецов нажата кнопка с ключем try
2024-07-31 12:53:39,879 INFO добавляю user: Максим Кузнецов
2024-07-31 12:53:40,445 INFO Максим Кузнецов успешно добавлен
2024-07-31 12:53:40,542 ERROR Infinity polling exception: [Errno 2] No such file or directory: '/root/bot_vpn/vpn_on.jpg'
2024-07-31 12:53:40,542 ERROR Exception traceback:
Traceback (most recent call last):
  File "/Library/Frameworks/Python.framework/Versions/3.10/lib/python3.10/site-packages/telebot/__init__.py", line 955, in infinity_polling
    self.polling(non_stop=True, timeout=timeout, long_polling_timeout=long_polling_timeout,
  File "/Library/Frameworks/Python.framework/Versions/3.10/lib/python3.10/site-packages/telebot/__init__.py", line 1043, in polling
    self.__threaded_polling(non_stop=non_stop, interval=interval, timeout=timeout, long_polling_timeout=long_polling_timeout,
  File "/Library/Frameworks/Python.framework/Versions/3.10/lib/python3.10/site-packages/telebot/__init__.py", line 1118, in __threaded_polling
    raise e
  File "/Library/Frameworks/Python.framework/Versions/3.10/lib/python3.10/site-packages/telebot/__init__.py", line 1074, in __threaded_polling
    self.worker_pool.raise_exceptions()
  File "/Library/Frameworks/Python.framework/Versions/3.10/lib/python3.10/site-packages/telebot/util.py", line 147, in raise_exceptions
    raise self.exception_info
  File "/Library/Frameworks/Python.framework/Versions/3.10/lib/python3.10/site-packages/telebot/util.py", line 90, in run
    task(*args, **kwargs)
  File "/Library/Frameworks/Python.framework/Versions/3.10/lib/python3.10/site-packages/telebot/__init__.py", line 6788, in _run_middlewares_and_handler
    result = handler['function'](message)
  File "/Users/mkuznecov/my_projects/bot_vpn/bot_vpn.py", line 254, in callback_woker
    successfully_paid(call.from_user.id, datetime_exit)
  File "/Users/mkuznecov/my_projects/bot_vpn/bot_vpn.py", line 32, in successfully_paid
    if bot.send_photo(id, open(config.FILE_URL + "vpn_on.jpg", "rb"),"*Спасибо что выбрали наш сервис\.*\n\nVPN готов к работе\. Для доступа необходимо скачать приложение для вашей платформы \(ссылки ниже по сообщению\), вставить в приложение ваш персональную ссылку\-ключ и нажать подключиться\.\n\nСсылка\-ключ: \n`" +
FileNotFoundError: [Errno 2] No such file or directory: '/root/bot_vpn/vpn_on.jpg'

2024-07-31 12:54:39,271 INFO .
2024-07-31 13:05:25,366 ERROR Infinity polling exception: column "server" does not exist
LINE 3: ...) FROM users_subscription WHERE action = True AND server = 2
                                                             ^
HINT:  Perhaps you meant to reference the column "users_subscription.server_id".

2024-07-31 13:05:25,366 ERROR Exception traceback:
Traceback (most recent call last):
  File "/Library/Frameworks/Python.framework/Versions/3.10/lib/python3.10/site-packages/telebot/__init__.py", line 955, in infinity_polling
    self.polling(non_stop=True, timeout=timeout, long_polling_timeout=long_polling_timeout,
  File "/Library/Frameworks/Python.framework/Versions/3.10/lib/python3.10/site-packages/telebot/__init__.py", line 1043, in polling
    self.__threaded_polling(non_stop=non_stop, interval=interval, timeout=timeout, long_polling_timeout=long_polling_timeout,
  File "/Library/Frameworks/Python.framework/Versions/3.10/lib/python3.10/site-packages/telebot/__init__.py", line 1118, in __threaded_polling
    raise e
  File "/Library/Frameworks/Python.framework/Versions/3.10/lib/python3.10/site-packages/telebot/__init__.py", line 1074, in __threaded_polling
    self.worker_pool.raise_exceptions()
  File "/Library/Frameworks/Python.framework/Versions/3.10/lib/python3.10/site-packages/telebot/util.py", line 147, in raise_exceptions
    raise self.exception_info
  File "/Library/Frameworks/Python.framework/Versions/3.10/lib/python3.10/site-packages/telebot/util.py", line 90, in run
    task(*args, **kwargs)
  File "/Library/Frameworks/Python.framework/Versions/3.10/lib/python3.10/site-packages/telebot/__init__.py", line 6788, in _run_middlewares_and_handler
    result = handler['function'](message)
  File "/Users/mkuznecov/my_projects/bot_vpn/bot_vpn.py", line 78, in define
    cursor.execute("SELECT COUNT(1) FROM users_subscription WHERE action=True"+
psycopg2.errors.UndefinedColumn: column "server" does not exist
LINE 3: ...) FROM users_subscription WHERE action = True AND server = 2
                                                             ^
HINT:  Perhaps you meant to reference the column "users_subscription.server_id".


2024-07-31 13:06:46,178 ERROR Threaded polling exception: A request to the Telegram API was unsuccessful. Error code: 409. Description: Conflict: terminated by other getUpdates request; make sure that only one bot instance is running
2024-07-31 13:06:46,179 ERROR Exception traceback:
Traceback (most recent call last):
  File "/Library/Frameworks/Python.framework/Versions/3.10/lib/python3.10/site-packages/telebot/__init__.py", line 1073, in __threaded_polling
    polling_thread.raise_exceptions()
  File "/Library/Frameworks/Python.framework/Versions/3.10/lib/python3.10/site-packages/telebot/util.py", line 108, in raise_exceptions
    raise self.exception_info
  File "/Library/Frameworks/Python.framework/Versions/3.10/lib/python3.10/site-packages/telebot/util.py", line 90, in run
    task(*args, **kwargs)
  File "/Library/Frameworks/Python.framework/Versions/3.10/lib/python3.10/site-packages/telebot/__init__.py", line 649, in __retrieve_updates
    updates = self.get_updates(offset=(self.last_update_id + 1),
  File "/Library/Frameworks/Python.framework/Versions/3.10/lib/python3.10/site-packages/telebot/__init__.py", line 623, in get_updates
    json_updates = apihelper.get_updates(self.token, offset, limit, timeout, allowed_updates, long_polling_timeout)
  File "/Library/Frameworks/Python.framework/Versions/3.10/lib/python3.10/site-packages/telebot/apihelper.py", line 321, in get_updates
    return _make_request(token, method_url, params=payload)
  File "/Library/Frameworks/Python.framework/Versions/3.10/lib/python3.10/site-packages/telebot/apihelper.py", line 162, in _make_request
    json_result = _check_result(method_name, result)
  File "/Library/Frameworks/Python.framework/Versions/3.10/lib/python3.10/site-packages/telebot/apihelper.py", line 189, in _check_result
    raise ApiTelegramException(method_name, result, result_json)
telebot.apihelper.ApiTelegramException: A request to the Telegram API was unsuccessful. Error code: 409. Description: Conflict: terminated by other getUpdates request; make sure that only one bot instance is running

2024-07-31 13:06:46,503 ERROR Infinity polling exception: can only concatenate str (not "int") to str
2024-07-31 13:06:46,504 ERROR Exception traceback:
Traceback (most recent call last):
  File "/Library/Frameworks/Python.framework/Versions/3.10/lib/python3.10/site-packages/telebot/__init__.py", line 955, in infinity_polling
    self.polling(non_stop=True, timeout=timeout, long_polling_timeout=long_polling_timeout,
  File "/Library/Frameworks/Python.framework/Versions/3.10/lib/python3.10/site-packages/telebot/__init__.py", line 1043, in polling
    self.__threaded_polling(non_stop=non_stop, interval=interval, timeout=timeout, long_polling_timeout=long_polling_timeout,
  File "/Library/Frameworks/Python.framework/Versions/3.10/lib/python3.10/site-packages/telebot/__init__.py", line 1118, in __threaded_polling
    raise e
  File "/Library/Frameworks/Python.framework/Versions/3.10/lib/python3.10/site-packages/telebot/__init__.py", line 1074, in __threaded_polling
    self.worker_pool.raise_exceptions()
  File "/Library/Frameworks/Python.framework/Versions/3.10/lib/python3.10/site-packages/telebot/util.py", line 147, in raise_exceptions
    raise self.exception_info
  File "/Library/Frameworks/Python.framework/Versions/3.10/lib/python3.10/site-packages/telebot/util.py", line 90, in run
    task(*args, **kwargs)
  File "/Library/Frameworks/Python.framework/Versions/3.10/lib/python3.10/site-packages/telebot/__init__.py", line 6788, in _run_middlewares_and_handler
    result = handler['function'](message)
  File "/Users/mkuznecov/my_projects/bot_vpn/bot_vpn.py", line 78, in define
    cursor.execute("SELECT COUNT(1) FROM users_subscription WHERE action=True"+
TypeError: can only concatenate str (not "int") to str

2024-07-31 13:06:53,341 ERROR Threaded polling exception: A request to the Telegram API was unsuccessful. Error code: 409. Description: Conflict: terminated by other getUpdates request; make sure that only one bot instance is running
2024-07-31 13:06:53,341 ERROR Exception traceback:
Traceback (most recent call last):
  File "/Library/Frameworks/Python.framework/Versions/3.10/lib/python3.10/site-packages/telebot/__init__.py", line 1073, in __threaded_polling
    polling_thread.raise_exceptions()
  File "/Library/Frameworks/Python.framework/Versions/3.10/lib/python3.10/site-packages/telebot/util.py", line 108, in raise_exceptions
    raise self.exception_info
  File "/Library/Frameworks/Python.framework/Versions/3.10/lib/python3.10/site-packages/telebot/util.py", line 90, in run
    task(*args, **kwargs)
  File "/Library/Frameworks/Python.framework/Versions/3.10/lib/python3.10/site-packages/telebot/__init__.py", line 649, in __retrieve_updates
    updates = self.get_updates(offset=(self.last_update_id + 1),
  File "/Library/Frameworks/Python.framework/Versions/3.10/lib/python3.10/site-packages/telebot/__init__.py", line 623, in get_updates
    json_updates = apihelper.get_updates(self.token, offset, limit, timeout, allowed_updates, long_polling_timeout)
  File "/Library/Frameworks/Python.framework/Versions/3.10/lib/python3.10/site-packages/telebot/apihelper.py", line 321, in get_updates
    return _make_request(token, method_url, params=payload)
  File "/Library/Frameworks/Python.framework/Versions/3.10/lib/python3.10/site-packages/telebot/apihelper.py", line 162, in _make_request
    json_result = _check_result(method_name, result)
  File "/Library/Frameworks/Python.framework/Versions/3.10/lib/python3.10/site-packages/telebot/apihelper.py", line 189, in _check_result
    raise ApiTelegramException(method_name, result, result_json)
telebot.apihelper.ApiTelegramException: A request to the Telegram API was unsuccessful. Error code: 409. Description: Conflict: terminated by other getUpdates request; make sure that only one bot instance is running

2024-07-31 14:47:19,405 ERROR Infinity polling exception: [Errno 2] No such file or directory: '/root/bot_vpn/vpn_on.jpg'
2024-07-31 14:47:19,406 ERROR Exception traceback:
Traceback (most recent call last):
  File "/Library/Frameworks/Python.framework/Versions/3.10/lib/python3.10/site-packages/telebot/__init__.py", line 955, in infinity_polling
    self.polling(non_stop=True, timeout=timeout, long_polling_timeout=long_polling_timeout,
  File "/Library/Frameworks/Python.framework/Versions/3.10/lib/python3.10/site-packages/telebot/__init__.py", line 1043, in polling
    self.__threaded_polling(non_stop=non_stop, interval=interval, timeout=timeout, long_polling_timeout=long_polling_timeout,
  File "/Library/Frameworks/Python.framework/Versions/3.10/lib/python3.10/site-packages/telebot/__init__.py", line 1118, in __threaded_polling
    raise e
  File "/Library/Frameworks/Python.framework/Versions/3.10/lib/python3.10/site-packages/telebot/__init__.py", line 1074, in __threaded_polling
    self.worker_pool.raise_exceptions()
  File "/Library/Frameworks/Python.framework/Versions/3.10/lib/python3.10/site-packages/telebot/util.py", line 147, in raise_exceptions
    raise self.exception_info
  File "/Library/Frameworks/Python.framework/Versions/3.10/lib/python3.10/site-packages/telebot/util.py", line 90, in run
    task(*args, **kwargs)
  File "/Library/Frameworks/Python.framework/Versions/3.10/lib/python3.10/site-packages/telebot/__init__.py", line 6788, in _run_middlewares_and_handler
    result = handler['function'](message)
  File "/Users/mkuznecov/my_projects/bot_vpn/bot_vpn.py", line 154, in start
    successfully_paid(message.from_user.id)
  File "/Users/mkuznecov/my_projects/bot_vpn/bot_vpn.py", line 32, in successfully_paid
    if bot.send_photo(id, open(config.FILE_URL + "vpn_on.jpg", "rb"), config.TextsMessages.successfullySubscription.value.format(
FileNotFoundError: [Errno 2] No such file or directory: '/root/bot_vpn/vpn_on.jpg'

2024-08-13 18:15:06,484 ERROR Infinity polling exception: Single '}' encountered in format string
2024-08-13 18:15:06,485 ERROR Exception traceback:
Traceback (most recent call last):
  File "/Library/Frameworks/Python.framework/Versions/3.10/lib/python3.10/site-packages/telebot/__init__.py", line 955, in infinity_polling
    self.polling(non_stop=True, timeout=timeout, long_polling_timeout=long_polling_timeout,
  File "/Library/Frameworks/Python.framework/Versions/3.10/lib/python3.10/site-packages/telebot/__init__.py", line 1043, in polling
    self.__threaded_polling(non_stop=non_stop, interval=interval, timeout=timeout, long_polling_timeout=long_polling_timeout,
  File "/Library/Frameworks/Python.framework/Versions/3.10/lib/python3.10/site-packages/telebot/__init__.py", line 1118, in __threaded_polling
    raise e
  File "/Library/Frameworks/Python.framework/Versions/3.10/lib/python3.10/site-packages/telebot/__init__.py", line 1074, in __threaded_polling
    self.worker_pool.raise_exceptions()
  File "/Library/Frameworks/Python.framework/Versions/3.10/lib/python3.10/site-packages/telebot/util.py", line 147, in raise_exceptions
    raise self.exception_info
  File "/Library/Frameworks/Python.framework/Versions/3.10/lib/python3.10/site-packages/telebot/util.py", line 90, in run
    task(*args, **kwargs)
  File "/Library/Frameworks/Python.framework/Versions/3.10/lib/python3.10/site-packages/telebot/__init__.py", line 6788, in _run_middlewares_and_handler
    result = handler['function'](message)
  File "/Users/mkuznecov/my_projects/bot_vpn/bot_vpn.py", line 172, in start
    successfully_paid(message.from_user.id)
  File "/Users/mkuznecov/my_projects/bot_vpn/bot_vpn.py", line 39, in successfully_paid
    response = requests.get("https://ulvis.net/api.php?url=http://80.209.243.179:8081/597730754/link/{}&custom={}}".format(data_cur["server_link"], data_cur["name"]))
ValueError: Single '}' encountered in format string

2024-08-13 18:15:37,565 ERROR Infinity polling exception: Expecting value: line 1 column 1 (char 0)
2024-08-13 18:15:37,565 ERROR Exception traceback:
Traceback (most recent call last):
  File "/Library/Frameworks/Python.framework/Versions/3.10/lib/python3.10/site-packages/telebot/__init__.py", line 955, in infinity_polling
    self.polling(non_stop=True, timeout=timeout, long_polling_timeout=long_polling_timeout,
  File "/Library/Frameworks/Python.framework/Versions/3.10/lib/python3.10/site-packages/telebot/__init__.py", line 1043, in polling
    self.__threaded_polling(non_stop=non_stop, interval=interval, timeout=timeout, long_polling_timeout=long_polling_timeout,
  File "/Library/Frameworks/Python.framework/Versions/3.10/lib/python3.10/site-packages/telebot/__init__.py", line 1118, in __threaded_polling
    raise e
  File "/Library/Frameworks/Python.framework/Versions/3.10/lib/python3.10/site-packages/telebot/__init__.py", line 1074, in __threaded_polling
    self.worker_pool.raise_exceptions()
  File "/Library/Frameworks/Python.framework/Versions/3.10/lib/python3.10/site-packages/telebot/util.py", line 147, in raise_exceptions
    raise self.exception_info
  File "/Library/Frameworks/Python.framework/Versions/3.10/lib/python3.10/site-packages/telebot/util.py", line 90, in run
    task(*args, **kwargs)
  File "/Library/Frameworks/Python.framework/Versions/3.10/lib/python3.10/site-packages/telebot/__init__.py", line 6788, in _run_middlewares_and_handler
    result = handler['function'](message)
  File "/Users/mkuznecov/my_projects/bot_vpn/bot_vpn.py", line 172, in start
    successfully_paid(message.from_user.id)
  File "/Users/mkuznecov/my_projects/bot_vpn/bot_vpn.py", line 40, in successfully_paid
    shortLink = response.json()
  File "/Library/Frameworks/Python.framework/Versions/3.10/lib/python3.10/site-packages/requests/models.py", line 910, in json
    return complexjson.loads(self.text, **kwargs)
  File "/Library/Frameworks/Python.framework/Versions/3.10/lib/python3.10/json/__init__.py", line 346, in loads
    return _default_decoder.decode(s)
  File "/Library/Frameworks/Python.framework/Versions/3.10/lib/python3.10/json/decoder.py", line 337, in decode
    obj, end = self.raw_decode(s, idx=_w(s, 0).end())
  File "/Library/Frameworks/Python.framework/Versions/3.10/lib/python3.10/json/decoder.py", line 355, in raw_decode
    raise JSONDecodeError("Expecting value", s, err.value) from None
json.decoder.JSONDecodeError: Expecting value: line 1 column 1 (char 0)

2024-08-13 18:16:36,304 ERROR Infinity polling exception: Expecting value: line 1 column 1 (char 0)
2024-08-13 18:16:36,305 ERROR Exception traceback:
Traceback (most recent call last):
  File "/Library/Frameworks/Python.framework/Versions/3.10/lib/python3.10/site-packages/telebot/__init__.py", line 955, in infinity_polling
    self.polling(non_stop=True, timeout=timeout, long_polling_timeout=long_polling_timeout,
  File "/Library/Frameworks/Python.framework/Versions/3.10/lib/python3.10/site-packages/telebot/__init__.py", line 1043, in polling
    self.__threaded_polling(non_stop=non_stop, interval=interval, timeout=timeout, long_polling_timeout=long_polling_timeout,
  File "/Library/Frameworks/Python.framework/Versions/3.10/lib/python3.10/site-packages/telebot/__init__.py", line 1118, in __threaded_polling
    raise e
  File "/Library/Frameworks/Python.framework/Versions/3.10/lib/python3.10/site-packages/telebot/__init__.py", line 1074, in __threaded_polling
    self.worker_pool.raise_exceptions()
  File "/Library/Frameworks/Python.framework/Versions/3.10/lib/python3.10/site-packages/telebot/util.py", line 147, in raise_exceptions
    raise self.exception_info
  File "/Library/Frameworks/Python.framework/Versions/3.10/lib/python3.10/site-packages/telebot/util.py", line 90, in run
    task(*args, **kwargs)
  File "/Library/Frameworks/Python.framework/Versions/3.10/lib/python3.10/site-packages/telebot/__init__.py", line 6788, in _run_middlewares_and_handler
    result = handler['function'](message)
  File "/Users/mkuznecov/my_projects/bot_vpn/bot_vpn.py", line 172, in start
    successfully_paid(message.from_user.id)
  File "/Users/mkuznecov/my_projects/bot_vpn/bot_vpn.py", line 40, in successfully_paid
    shortLink = response.json()
  File "/Library/Frameworks/Python.framework/Versions/3.10/lib/python3.10/site-packages/requests/models.py", line 910, in json
    return complexjson.loads(self.text, **kwargs)
  File "/Library/Frameworks/Python.framework/Versions/3.10/lib/python3.10/json/__init__.py", line 346, in loads
    return _default_decoder.decode(s)
  File "/Library/Frameworks/Python.framework/Versions/3.10/lib/python3.10/json/decoder.py", line 337, in decode
    obj, end = self.raw_decode(s, idx=_w(s, 0).end())
  File "/Library/Frameworks/Python.framework/Versions/3.10/lib/python3.10/json/decoder.py", line 355, in raw_decode
    raise JSONDecodeError("Expecting value", s, err.value) from None
json.decoder.JSONDecodeError: Expecting value: line 1 column 1 (char 0)

2024-08-13 18:24:16,769 ERROR Infinity polling exception: Expecting value: line 1 column 1 (char 0)
2024-08-13 18:24:16,769 ERROR Exception traceback:
Traceback (most recent call last):
  File "/Library/Frameworks/Python.framework/Versions/3.10/lib/python3.10/site-packages/telebot/__init__.py", line 955, in infinity_polling
    self.polling(non_stop=True, timeout=timeout, long_polling_timeout=long_polling_timeout,
  File "/Library/Frameworks/Python.framework/Versions/3.10/lib/python3.10/site-packages/telebot/__init__.py", line 1043, in polling
    self.__threaded_polling(non_stop=non_stop, interval=interval, timeout=timeout, long_polling_timeout=long_polling_timeout,
  File "/Library/Frameworks/Python.framework/Versions/3.10/lib/python3.10/site-packages/telebot/__init__.py", line 1118, in __threaded_polling
    raise e
  File "/Library/Frameworks/Python.framework/Versions/3.10/lib/python3.10/site-packages/telebot/__init__.py", line 1074, in __threaded_polling
    self.worker_pool.raise_exceptions()
  File "/Library/Frameworks/Python.framework/Versions/3.10/lib/python3.10/site-packages/telebot/util.py", line 147, in raise_exceptions
    raise self.exception_info
  File "/Library/Frameworks/Python.framework/Versions/3.10/lib/python3.10/site-packages/telebot/util.py", line 90, in run
    task(*args, **kwargs)
  File "/Library/Frameworks/Python.framework/Versions/3.10/lib/python3.10/site-packages/telebot/__init__.py", line 6788, in _run_middlewares_and_handler
    result = handler['function'](message)
  File "/Users/mkuznecov/my_projects/bot_vpn/bot_vpn.py", line 172, in start
    successfully_paid(message.from_user.id)
  File "/Users/mkuznecov/my_projects/bot_vpn/bot_vpn.py", line 41, in successfully_paid
    print("response: ", response.json())
  File "/Library/Frameworks/Python.framework/Versions/3.10/lib/python3.10/site-packages/requests/models.py", line 910, in json
    return complexjson.loads(self.text, **kwargs)
  File "/Library/Frameworks/Python.framework/Versions/3.10/lib/python3.10/json/__init__.py", line 346, in loads
    return _default_decoder.decode(s)
  File "/Library/Frameworks/Python.framework/Versions/3.10/lib/python3.10/json/decoder.py", line 337, in decode
    obj, end = self.raw_decode(s, idx=_w(s, 0).end())
  File "/Library/Frameworks/Python.framework/Versions/3.10/lib/python3.10/json/decoder.py", line 355, in raw_decode
    raise JSONDecodeError("Expecting value", s, err.value) from None
json.decoder.JSONDecodeError: Expecting value: line 1 column 1 (char 0)

2024-08-13 19:32:46,426 ERROR Infinity polling exception: [Errno 2] No such file or directory: '/root/bot_vpn/vpn_on.png'
2024-08-13 19:32:46,427 ERROR Exception traceback:
Traceback (most recent call last):
  File "/Library/Frameworks/Python.framework/Versions/3.10/lib/python3.10/site-packages/telebot/__init__.py", line 955, in infinity_polling
    self.polling(non_stop=True, timeout=timeout, long_polling_timeout=long_polling_timeout,
  File "/Library/Frameworks/Python.framework/Versions/3.10/lib/python3.10/site-packages/telebot/__init__.py", line 1043, in polling
    self.__threaded_polling(non_stop=non_stop, interval=interval, timeout=timeout, long_polling_timeout=long_polling_timeout,
  File "/Library/Frameworks/Python.framework/Versions/3.10/lib/python3.10/site-packages/telebot/__init__.py", line 1118, in __threaded_polling
    raise e
  File "/Library/Frameworks/Python.framework/Versions/3.10/lib/python3.10/site-packages/telebot/__init__.py", line 1074, in __threaded_polling
    self.worker_pool.raise_exceptions()
  File "/Library/Frameworks/Python.framework/Versions/3.10/lib/python3.10/site-packages/telebot/util.py", line 147, in raise_exceptions
    raise self.exception_info
  File "/Library/Frameworks/Python.framework/Versions/3.10/lib/python3.10/site-packages/telebot/util.py", line 90, in run
    task(*args, **kwargs)
  File "/Library/Frameworks/Python.framework/Versions/3.10/lib/python3.10/site-packages/telebot/__init__.py", line 6788, in _run_middlewares_and_handler
    result = handler['function'](message)
  File "/Users/mkuznecov/my_projects/bot_vpn/bot_vpn.py", line 171, in start
    successfully_paid(message.from_user.id)
  File "/Users/mkuznecov/my_projects/bot_vpn/bot_vpn.py", line 41, in successfully_paid
    if bot.send_photo(id, open(config.FILE_URL + "vpn_on.png", "rb"), config.TextsMessages.successfullySubscription.value.format(
FileNotFoundError: [Errno 2] No such file or directory: '/root/bot_vpn/vpn_on.png'

2024-08-15 16:44:02,032 ERROR Threaded polling exception: A request to the Telegram API was unsuccessful. Error code: 400. Description: Bad Request: inline keyboard button Web App URL 'google.com' is invalid: Only HTTPS links are allowed
2024-08-15 16:44:02,033 ERROR Exception traceback:
Traceback (most recent call last):
  File "/Library/Frameworks/Python.framework/Versions/3.10/lib/python3.10/site-packages/telebot/__init__.py", line 1074, in __threaded_polling
    self.worker_pool.raise_exceptions()
  File "/Library/Frameworks/Python.framework/Versions/3.10/lib/python3.10/site-packages/telebot/util.py", line 147, in raise_exceptions
    raise self.exception_info
  File "/Library/Frameworks/Python.framework/Versions/3.10/lib/python3.10/site-packages/telebot/util.py", line 90, in run
    task(*args, **kwargs)
  File "/Library/Frameworks/Python.framework/Versions/3.10/lib/python3.10/site-packages/telebot/__init__.py", line 6788, in _run_middlewares_and_handler
    result = handler['function'](message)
  File "/Users/mkuznecov/my_projects/bot_vpn/bot_vpn.py", line 172, in start
    successfully_paid(message.from_user.id)
  File "/Users/mkuznecov/my_projects/bot_vpn/bot_vpn.py", line 42, in successfully_paid
    if bot.send_message(id, config.TextsMessages.successfullySubscription.value.format(
  File "/Library/Frameworks/Python.framework/Versions/3.10/lib/python3.10/site-packages/telebot/__init__.py", line 1549, in send_message
    apihelper.send_message(
  File "/Library/Frameworks/Python.framework/Versions/3.10/lib/python3.10/site-packages/telebot/apihelper.py", line 264, in send_message
    return _make_request(token, method_url, params=payload, method='post')
  File "/Library/Frameworks/Python.framework/Versions/3.10/lib/python3.10/site-packages/telebot/apihelper.py", line 162, in _make_request
    json_result = _check_result(method_name, result)
  File "/Library/Frameworks/Python.framework/Versions/3.10/lib/python3.10/site-packages/telebot/apihelper.py", line 189, in _check_result
    raise ApiTelegramException(method_name, result, result_json)
telebot.apihelper.ApiTelegramException: A request to the Telegram API was unsuccessful. Error code: 400. Description: Bad Request: inline keyboard button Web App URL 'google.com' is invalid: Only HTTPS links are allowed

2024-08-15 16:44:49,031 INFO chat: None, user:Максим Кузнецов нажата кнопка с ключем sale
2024-08-15 16:44:49,040 ERROR Infinity polling exception: [Errno 2] No such file or directory: '/root/bot_vpn/vpn_option.png'
2024-08-15 16:44:49,040 ERROR Exception traceback:
Traceback (most recent call last):
  File "/Library/Frameworks/Python.framework/Versions/3.10/lib/python3.10/site-packages/telebot/__init__.py", line 955, in infinity_polling
    self.polling(non_stop=True, timeout=timeout, long_polling_timeout=long_polling_timeout,
  File "/Library/Frameworks/Python.framework/Versions/3.10/lib/python3.10/site-packages/telebot/__init__.py", line 1043, in polling
    self.__threaded_polling(non_stop=non_stop, interval=interval, timeout=timeout, long_polling_timeout=long_polling_timeout,
  File "/Library/Frameworks/Python.framework/Versions/3.10/lib/python3.10/site-packages/telebot/__init__.py", line 1118, in __threaded_polling
    raise e
  File "/Library/Frameworks/Python.framework/Versions/3.10/lib/python3.10/site-packages/telebot/__init__.py", line 1074, in __threaded_polling
    self.worker_pool.raise_exceptions()
  File "/Library/Frameworks/Python.framework/Versions/3.10/lib/python3.10/site-packages/telebot/util.py", line 147, in raise_exceptions
    raise self.exception_info
  File "/Library/Frameworks/Python.framework/Versions/3.10/lib/python3.10/site-packages/telebot/util.py", line 90, in run
    task(*args, **kwargs)
  File "/Library/Frameworks/Python.framework/Versions/3.10/lib/python3.10/site-packages/telebot/__init__.py", line 6788, in _run_middlewares_and_handler
    result = handler['function'](message)
  File "/Users/mkuznecov/my_projects/bot_vpn/bot_vpn.py", line 308, in callback_woker
    photo = open(config.FILE_URL + "vpn_option.png", "rb"),
FileNotFoundError: [Errno 2] No such file or directory: '/root/bot_vpn/vpn_option.png'

2024-08-25 11:57:46,195 ERROR Infinity polling exception: [Errno 2] No such file or directory: '/root/bot_vpn/4rrr.jpg'
2024-08-25 11:57:46,202 ERROR Exception traceback:
Traceback (most recent call last):
  File "/Library/Frameworks/Python.framework/Versions/3.10/lib/python3.10/site-packages/telebot/__init__.py", line 955, in infinity_polling
    self.polling(non_stop=True, timeout=timeout, long_polling_timeout=long_polling_timeout,
  File "/Library/Frameworks/Python.framework/Versions/3.10/lib/python3.10/site-packages/telebot/__init__.py", line 1043, in polling
    self.__threaded_polling(non_stop=non_stop, interval=interval, timeout=timeout, long_polling_timeout=long_polling_timeout,
  File "/Library/Frameworks/Python.framework/Versions/3.10/lib/python3.10/site-packages/telebot/__init__.py", line 1118, in __threaded_polling
    raise e
  File "/Library/Frameworks/Python.framework/Versions/3.10/lib/python3.10/site-packages/telebot/__init__.py", line 1074, in __threaded_polling
    self.worker_pool.raise_exceptions()
  File "/Library/Frameworks/Python.framework/Versions/3.10/lib/python3.10/site-packages/telebot/util.py", line 147, in raise_exceptions
    raise self.exception_info
  File "/Library/Frameworks/Python.framework/Versions/3.10/lib/python3.10/site-packages/telebot/util.py", line 90, in run
    task(*args, **kwargs)
  File "/Library/Frameworks/Python.framework/Versions/3.10/lib/python3.10/site-packages/telebot/__init__.py", line 6788, in _run_middlewares_and_handler
    result = handler['function'](message)
  File "/Users/mkuznecov/my_projects/bot_vpn/bot_vpn.py", line 197, in start
    successfully_paid(message.from_user.id)
  File "/Users/mkuznecov/my_projects/bot_vpn/bot_vpn.py", line 43, in successfully_paid
    if bot.send_photo(chat_id=id, photo=open(config.FILE_URL + "4rrr.jpg", "rb"),
FileNotFoundError: [Errno 2] No such file or directory: '/root/bot_vpn/4rrr.jpg'

2024-08-25 11:59:55,823 ERROR Infinity polling exception: module 'getPayLink' has no attribute 'getOrderList'
2024-08-25 11:59:55,824 ERROR Exception traceback:
Traceback (most recent call last):
  File "/Library/Frameworks/Python.framework/Versions/3.10/lib/python3.10/site-packages/telebot/__init__.py", line 955, in infinity_polling
    self.polling(non_stop=True, timeout=timeout, long_polling_timeout=long_polling_timeout,
  File "/Library/Frameworks/Python.framework/Versions/3.10/lib/python3.10/site-packages/telebot/__init__.py", line 1043, in polling
    self.__threaded_polling(non_stop=non_stop, interval=interval, timeout=timeout, long_polling_timeout=long_polling_timeout,
  File "/Library/Frameworks/Python.framework/Versions/3.10/lib/python3.10/site-packages/telebot/__init__.py", line 1118, in __threaded_polling
    raise e
  File "/Library/Frameworks/Python.framework/Versions/3.10/lib/python3.10/site-packages/telebot/__init__.py", line 1074, in __threaded_polling
    self.worker_pool.raise_exceptions()
  File "/Library/Frameworks/Python.framework/Versions/3.10/lib/python3.10/site-packages/telebot/util.py", line 147, in raise_exceptions
    raise self.exception_info
  File "/Library/Frameworks/Python.framework/Versions/3.10/lib/python3.10/site-packages/telebot/util.py", line 90, in run
    task(*args, **kwargs)
  File "/Library/Frameworks/Python.framework/Versions/3.10/lib/python3.10/site-packages/telebot/__init__.py", line 6788, in _run_middlewares_and_handler
    result = handler['function'](message)
  File "/Users/mkuznecov/my_projects/bot_vpn/bot_vpn.py", line 238, in text_handler
    getPayLink.getOrderList()
AttributeError: module 'getPayLink' has no attribute 'getOrderList'

2024-08-25 11:59:58,829 ERROR Infinity polling exception: module 'getPayLink' has no attribute 'getOrderList'
2024-08-25 11:59:58,830 ERROR Exception traceback:
Traceback (most recent call last):
  File "/Library/Frameworks/Python.framework/Versions/3.10/lib/python3.10/site-packages/telebot/__init__.py", line 955, in infinity_polling
    self.polling(non_stop=True, timeout=timeout, long_polling_timeout=long_polling_timeout,
  File "/Library/Frameworks/Python.framework/Versions/3.10/lib/python3.10/site-packages/telebot/__init__.py", line 1043, in polling
    self.__threaded_polling(non_stop=non_stop, interval=interval, timeout=timeout, long_polling_timeout=long_polling_timeout,
  File "/Library/Frameworks/Python.framework/Versions/3.10/lib/python3.10/site-packages/telebot/__init__.py", line 1118, in __threaded_polling
    raise e
  File "/Library/Frameworks/Python.framework/Versions/3.10/lib/python3.10/site-packages/telebot/__init__.py", line 1074, in __threaded_polling
    self.worker_pool.raise_exceptions()
  File "/Library/Frameworks/Python.framework/Versions/3.10/lib/python3.10/site-packages/telebot/util.py", line 147, in raise_exceptions
    raise self.exception_info
  File "/Library/Frameworks/Python.framework/Versions/3.10/lib/python3.10/site-packages/telebot/util.py", line 90, in run
    task(*args, **kwargs)
  File "/Library/Frameworks/Python.framework/Versions/3.10/lib/python3.10/site-packages/telebot/__init__.py", line 6788, in _run_middlewares_and_handler
    result = handler['function'](message)
  File "/Users/mkuznecov/my_projects/bot_vpn/bot_vpn.py", line 238, in text_handler
    getPayLink.getOrderList()
AttributeError: module 'getPayLink' has no attribute 'getOrderList'

2024-08-25 12:01:07,308 INFO test
2024-08-26 15:22:47,077 ERROR Infinity polling exception: [Errno 2] No such file or directory: '/root/bot_vpn/4rrr.jpg'
2024-08-26 15:22:47,079 ERROR Exception traceback:
Traceback (most recent call last):
  File "/Library/Frameworks/Python.framework/Versions/3.10/lib/python3.10/site-packages/telebot/__init__.py", line 955, in infinity_polling
    self.polling(non_stop=True, timeout=timeout, long_polling_timeout=long_polling_timeout,
  File "/Library/Frameworks/Python.framework/Versions/3.10/lib/python3.10/site-packages/telebot/__init__.py", line 1043, in polling
    self.__threaded_polling(non_stop=non_stop, interval=interval, timeout=timeout, long_polling_timeout=long_polling_timeout,
  File "/Library/Frameworks/Python.framework/Versions/3.10/lib/python3.10/site-packages/telebot/__init__.py", line 1118, in __threaded_polling
    raise e
  File "/Library/Frameworks/Python.framework/Versions/3.10/lib/python3.10/site-packages/telebot/__init__.py", line 1074, in __threaded_polling
    self.worker_pool.raise_exceptions()
  File "/Library/Frameworks/Python.framework/Versions/3.10/lib/python3.10/site-packages/telebot/util.py", line 147, in raise_exceptions
    raise self.exception_info
  File "/Library/Frameworks/Python.framework/Versions/3.10/lib/python3.10/site-packages/telebot/util.py", line 90, in run
    task(*args, **kwargs)
  File "/Library/Frameworks/Python.framework/Versions/3.10/lib/python3.10/site-packages/telebot/__init__.py", line 6788, in _run_middlewares_and_handler
    result = handler['function'](message)
  File "/Users/mkuznecov/my_projects/bot_vpn/bot_vpn.py", line 233, in start
    successfully_paid(message.from_user.id)
  File "/Users/mkuznecov/my_projects/bot_vpn/bot_vpn.py", line 51, in successfully_paid
    if bot.send_photo(chat_id=id, photo=open(config.FILE_URL + "4rrr.jpg", "rb"),
FileNotFoundError: [Errno 2] No such file or directory: '/root/bot_vpn/4rrr.jpg'

2024-08-26 15:26:39,958 INFO chat: None, user:Максим Кузнецов нажата кнопка с ключем sale
2024-08-26 15:26:39,964 ERROR Infinity polling exception: can only concatenate str (not "int") to str
2024-08-26 15:26:39,964 ERROR Exception traceback:
Traceback (most recent call last):
  File "/Library/Frameworks/Python.framework/Versions/3.10/lib/python3.10/site-packages/telebot/__init__.py", line 955, in infinity_polling
    self.polling(non_stop=True, timeout=timeout, long_polling_timeout=long_polling_timeout,
  File "/Library/Frameworks/Python.framework/Versions/3.10/lib/python3.10/site-packages/telebot/__init__.py", line 1043, in polling
    self.__threaded_polling(non_stop=non_stop, interval=interval, timeout=timeout, long_polling_timeout=long_polling_timeout,
  File "/Library/Frameworks/Python.framework/Versions/3.10/lib/python3.10/site-packages/telebot/__init__.py", line 1118, in __threaded_polling
    raise e
  File "/Library/Frameworks/Python.framework/Versions/3.10/lib/python3.10/site-packages/telebot/__init__.py", line 1074, in __threaded_polling
    self.worker_pool.raise_exceptions()
  File "/Library/Frameworks/Python.framework/Versions/3.10/lib/python3.10/site-packages/telebot/util.py", line 147, in raise_exceptions
    raise self.exception_info
  File "/Library/Frameworks/Python.framework/Versions/3.10/lib/python3.10/site-packages/telebot/util.py", line 90, in run
    task(*args, **kwargs)
  File "/Library/Frameworks/Python.framework/Versions/3.10/lib/python3.10/site-packages/telebot/__init__.py", line 6788, in _run_middlewares_and_handler
    result = handler['function'](message)
  File "/Users/mkuznecov/my_projects/bot_vpn/bot_vpn.py", line 393, in callback_woker
    keyboard.add(types.InlineKeyboardButton(text= stars[ServerUrl.niderlands.value] + "Нидерланды" + stars[ServerUrl.niderlands.value], callback_data='{"key": "getLinkPayment", "server": ' + Servers.niderlands.value + '}'),
TypeError: can only concatenate str (not "int") to str

2024-08-26 15:27:16,923 INFO chat: None, user:Максим Кузнецов нажата кнопка с ключем sale
2024-08-26 15:27:16,930 ERROR Infinity polling exception: [Errno 2] No such file or directory: '/root/bot_vpn/vpn_option.png'
2024-08-26 15:27:16,931 ERROR Exception traceback:
Traceback (most recent call last):
  File "/Library/Frameworks/Python.framework/Versions/3.10/lib/python3.10/site-packages/telebot/__init__.py", line 955, in infinity_polling
    self.polling(non_stop=True, timeout=timeout, long_polling_timeout=long_polling_timeout,
  File "/Library/Frameworks/Python.framework/Versions/3.10/lib/python3.10/site-packages/telebot/__init__.py", line 1043, in polling
    self.__threaded_polling(non_stop=non_stop, interval=interval, timeout=timeout, long_polling_timeout=long_polling_timeout,
  File "/Library/Frameworks/Python.framework/Versions/3.10/lib/python3.10/site-packages/telebot/__init__.py", line 1118, in __threaded_polling
    raise e
  File "/Library/Frameworks/Python.framework/Versions/3.10/lib/python3.10/site-packages/telebot/__init__.py", line 1074, in __threaded_polling
    self.worker_pool.raise_exceptions()
  File "/Library/Frameworks/Python.framework/Versions/3.10/lib/python3.10/site-packages/telebot/util.py", line 147, in raise_exceptions
    raise self.exception_info
  File "/Library/Frameworks/Python.framework/Versions/3.10/lib/python3.10/site-packages/telebot/util.py", line 90, in run
    task(*args, **kwargs)
  File "/Library/Frameworks/Python.framework/Versions/3.10/lib/python3.10/site-packages/telebot/__init__.py", line 6788, in _run_middlewares_and_handler
    result = handler['function'](message)
  File "/Users/mkuznecov/my_projects/bot_vpn/bot_vpn.py", line 396, in callback_woker
    photo = open(config.FILE_URL + "vpn_option.png", "rb"),
FileNotFoundError: [Errno 2] No such file or directory: '/root/bot_vpn/vpn_option.png'

2024-08-26 15:27:52,576 INFO chat: None, user:Максим Кузнецов нажата кнопка с ключем sale
2024-08-26 15:27:57,402 INFO chat: None, user:Максим Кузнецов нажата кнопка с ключем getLinkPayment
2024-08-26 15:27:57,980 ERROR Threaded polling exception: A request to the Telegram API was unsuccessful. Error code: 400. Description: Bad Request: message identifier is not specified
2024-08-26 15:27:57,980 ERROR Exception traceback:
Traceback (most recent call last):
  File "/Library/Frameworks/Python.framework/Versions/3.10/lib/python3.10/site-packages/telebot/__init__.py", line 1074, in __threaded_polling
    self.worker_pool.raise_exceptions()
  File "/Library/Frameworks/Python.framework/Versions/3.10/lib/python3.10/site-packages/telebot/util.py", line 147, in raise_exceptions
    raise self.exception_info
  File "/Library/Frameworks/Python.framework/Versions/3.10/lib/python3.10/site-packages/telebot/util.py", line 90, in run
    task(*args, **kwargs)
  File "/Library/Frameworks/Python.framework/Versions/3.10/lib/python3.10/site-packages/telebot/__init__.py", line 6788, in _run_middlewares_and_handler
    result = handler['function'](message)
  File "/Users/mkuznecov/my_projects/bot_vpn/bot_vpn.py", line 416, in callback_woker
    bot.edit_message_caption("Вы выбали сервер.\n", reply_markup=keyboard)
  File "/Library/Frameworks/Python.framework/Versions/3.10/lib/python3.10/site-packages/telebot/__init__.py", line 4494, in edit_message_caption
    result = apihelper.edit_message_caption(self.token, caption, chat_id, message_id, inline_message_id,
  File "/Library/Frameworks/Python.framework/Versions/3.10/lib/python3.10/site-packages/telebot/apihelper.py", line 1339, in edit_message_caption
    return _make_request(token, method_url, params=payload, method='post')
  File "/Library/Frameworks/Python.framework/Versions/3.10/lib/python3.10/site-packages/telebot/apihelper.py", line 162, in _make_request
    json_result = _check_result(method_name, result)
  File "/Library/Frameworks/Python.framework/Versions/3.10/lib/python3.10/site-packages/telebot/apihelper.py", line 189, in _check_result
    raise ApiTelegramException(method_name, result, result_json)
telebot.apihelper.ApiTelegramException: A request to the Telegram API was unsuccessful. Error code: 400. Description: Bad Request: message identifier is not specified

2024-08-26 15:28:52,931 INFO chat: None, user:Максим Кузнецов нажата кнопка с ключем sale
2024-08-26 15:28:55,193 INFO chat: None, user:Максим Кузнецов нажата кнопка с ключем getLinkPayment
2024-08-26 15:30:33,485 INFO chat: None, user:Максим Кузнецов нажата кнопка с ключем sale
2024-08-26 15:30:36,526 INFO chat: None, user:Максим Кузнецов нажата кнопка с ключем getLinkPayment
2024-08-26 15:34:43,814 INFO chat: None, user:Максим Кузнецов нажата кнопка с ключем sale
2024-08-26 15:34:45,815 INFO chat: None, user:Максим Кузнецов нажата кнопка с ключем getLinkPayment
2024-08-26 15:37:34,770 INFO chat: None, user:Максим Кузнецов нажата кнопка с ключем sale
2024-08-26 15:37:38,565 INFO chat: None, user:Максим Кузнецов нажата кнопка с ключем getLinkPayment
2024-08-26 15:39:05,887 INFO chat: None, user:Максим Кузнецов нажата кнопка с ключем sale
2024-08-26 15:39:07,992 INFO chat: None, user:Максим Кузнецов нажата кнопка с ключем getLinkPayment
2024-08-26 15:44:03,414 INFO chat: None, user:Максим Кузнецов нажата кнопка с ключем sale
2024-08-26 15:44:05,699 INFO chat: None, user:Максим Кузнецов нажата кнопка с ключем getLinkPayment
2024-08-26 15:44:05,707 ERROR Infinity polling exception: local variable 'time' referenced before assignment
2024-08-26 15:44:05,708 ERROR Exception traceback:
Traceback (most recent call last):
  File "/Library/Frameworks/Python.framework/Versions/3.10/lib/python3.10/site-packages/telebot/__init__.py", line 955, in infinity_polling
    self.polling(non_stop=True, timeout=timeout, long_polling_timeout=long_polling_timeout,
  File "/Library/Frameworks/Python.framework/Versions/3.10/lib/python3.10/site-packages/telebot/__init__.py", line 1043, in polling
    self.__threaded_polling(non_stop=non_stop, interval=interval, timeout=timeout, long_polling_timeout=long_polling_timeout,
  File "/Library/Frameworks/Python.framework/Versions/3.10/lib/python3.10/site-packages/telebot/__init__.py", line 1118, in __threaded_polling
    raise e
  File "/Library/Frameworks/Python.framework/Versions/3.10/lib/python3.10/site-packages/telebot/__init__.py", line 1074, in __threaded_polling
    self.worker_pool.raise_exceptions()
  File "/Library/Frameworks/Python.framework/Versions/3.10/lib/python3.10/site-packages/telebot/util.py", line 147, in raise_exceptions
    raise self.exception_info
  File "/Library/Frameworks/Python.framework/Versions/3.10/lib/python3.10/site-packages/telebot/util.py", line 90, in run
    task(*args, **kwargs)
  File "/Library/Frameworks/Python.framework/Versions/3.10/lib/python3.10/site-packages/telebot/__init__.py", line 6788, in _run_middlewares_and_handler
    result = handler['function'](message)
  File "/Users/mkuznecov/my_projects/bot_vpn/bot_vpn.py", line 411, in callback_woker
    label = time.time()
UnboundLocalError: local variable 'time' referenced before assignment

2024-08-26 15:47:15,967 INFO chat: None, user:Максим Кузнецов нажата кнопка с ключем sale
2024-08-26 15:47:17,850 INFO chat: None, user:Максим Кузнецов нажата кнопка с ключем getLinkPayment
2024-12-30 21:04:03,638 ERROR Подключиться к БД не удалось: connection to server at "66.151.32.210", port 5432 failed: Connection refused
	Is the server running on that host and accepting TCP/IP connections?

2024-12-30 21:05:03,353 ERROR Подключиться к БД не удалось: connection to server at "66.151.32.210", port 5432 failed: Connection refused
	Is the server running on that host and accepting TCP/IP connections?

